<mujoco model="five link walker">
	<compiler 	angle="radian" eulerseq="XYZ" balanceinertia="true"/>

	<worldbody>
	<!-- set up a light pointing down on the robot -->
		<light directional="true" pos="-0.5 0.5 3" dir="0 0 -1" />
		<!-- add a floor so we don't stare off into the abyss -->
		<geom name="floor" pos="0 0 0" size="1 1 1" type="plane" rgba="1 0.83 0.61 0.5"  contype="1" conaffinity="1"/>
		<!--start building model-->
	
		<body name="base" pos="0 0 0.8">
			<!-- uncomment to get planar joint - limit motion to just sagittal plane -->
			<joint name="base_x" type="slide" axis="1 0 0" pos="0 0 0"/>
			<joint name="base_z" type="slide" axis="0 0 1" pos="0 0 0"/>
			<joint name="rot_y" type="hinge" axis="0 1 0" pos="0 0 0"/>
			<geom name="torso" type="cylinder" size="0.025 0.315" pos="0 0 0.315" euler="0 0 0" rgba="0 255 61 0.9"  contype="5" conaffinity="3"  />
			<inertial pos="0 0 0.24" mass="12" diaginertia="0 1.33 0"/>
			<!-- uncomment to get free joint represented by quartenions -->
			<!--<joint type='free' limited='false'/>-->

		


			<!-- nest each child piece inside the parent body tags -->
			<body name="right_thigh" pos="0 0 0">
				
				<joint name="q1_right" axis="0 1 0" pos="0 0 0"/>
				<geom name="right_thigh" type="cylinder" size="0.025 0.2" pos="0 0 -0.2" euler="0 0 0" rgba="0 0 1 1"  contype="4" conaffinity="1"/>

				<inertial pos="0 0 -0.11" mass="6.8" diaginertia="0 0.47 0"/>
				<body name="right_shin" pos="0 0 -0.4">
				
					<joint name="q2_right" axis="0 1 0" pos="0 0 0"/>
					<geom name="right_shin" type="cylinder" size="0.025 0.2" pos="0 0 -0.2" euler="0 0 0" rgba="1 0 0 1" contype="4" conaffinity="1" />
					<inertial pos="0 0 -0.24" mass="6.8" diaginertia="0 0.2 0"/>
					
					 <geom name="right_foot" type="capsule" size="0.025 0.0125" pos="0 0 -0.4" euler="0 1.57 0" rgba="142 0 71 1" contype="4" conaffinity="1"/> 
					<!-- <geom name="right_foot" type="capsule" size="0.025 0.25" pos="0 0 -0.4" euler="0 1.57 0" rgba="142 0 71 1" contype="4" conaffinity="1"/> -->

				</body> 
			</body> 		

			<body name="left_thigh" pos="0 0 0">
				
				<joint name="q1_left" axis="0 1 0" pos="0 0 0"/>
				<geom name="left_thigh" type="cylinder" size="0.025 0.2" pos="0 0 -0.2" euler="0 0 0" rgba="0 0 1 1" contype="4" conaffinity="1"/>

				<inertial pos="0 0 -0.11" mass="6.8" diaginertia="0 0.47 0"/>
				<body name="left_shin" pos="0 0 -0.4">
				
					<joint name="q2_left" axis="0 1 0" pos="0 0 0"/>
					<geom name="left_shin" type="cylinder" size="0.025 0.2" pos="0 0 -0.2" euler="0 0 0" rgba="1 0 0 1" contype="4" conaffinity="1"/>
					<inertial pos="0 0 -0.24" mass="6.8" diaginertia="0 0.2 0"/>
					
					<geom name="left_foot" type="capsule" size="0.025 0.0125" pos="0 0 -0.4" euler="0 1.57 0" rgba="142 0 71 1" contype="4" conaffinity="1" /> 
					<!--<geom name="left_foot" type="capsule" size="0.025 0.25" pos="0 0 -0.4" euler="0 1.57 0" rgba="142 0 71 1" contype="4" conaffinity="1" /> --> 

				</body>		
			</body>



		</body> 
	</worldbody>

<!-- attach actuators to joints -->
    <actuator>
        <motor name="q1_right_motor" joint="q1_right" gear="50" />
        <motor name="q2_right_motor" joint="q2_right" gear="50"/>
	<motor name="q1_left_motor" joint="q1_left" gear="50" />
        <motor name="q2_left_motor" joint="q2_left" gear="50"/>
    </actuator>


   
</mujoco>
